Workbook

Sheet raw
A1: Nom | B1: Marque | C1: Groupe(s) / Société(s) cosmétique(s) | D1: Gamme | E1: Catégorie(s) cosmétique(s) | F1: Zone(s) d'application | G1: Type(s) de produit - Formulation(s) / Galénique(s) | H1: Cible(s) cosmétique(s) | I1: Conseils d'utilisation | J1: Ingrédients | K1: Article(s) de conditionnement / Packaging | L1: Contenance | M1: Made in | N1: Code EAN | O1: Inclusao
A2: DOUBLE WEAR - TEINT LONGUE TENUE POUDRE MAT | B2: ESTÉE LAUDER | C2: THE ESTÉE LAUDER COS. | D2: DOUBLE WEAR | E2: MAQUILLAGE | F2: VISAGE | G2: FOND DE TEINT,POUDRE | H2: TOUTES CARNATIONS | I2: Personnalisez votre couvrance avec l’applicateur double face : - Utilisez le côté éponge pour une application couvrante du fond de teint poudre sur l’ensemble du visage. - Utilisez le côté velours pour une couvrance plus douce ou ciblée. | J2: INCI TEINTE 3N1 IVORY BEIGE : SYNTHETIC FLUORPHLOGOPITE,ZINC STEARATE,BORON NITRIDE,SILICA,ALUMINA,POLYGLYCERYL-3 DIISOSTEARATE,LAUROYL LYSINE,BUTYLENE GLYCOL DICAPRYLATE/DICAPRATE,MAGNESIUM CARBONATE,TRIETHOXYCAPRYLYLSILANE,TOCOPHEROL,CAPRYLIC/CAPRIC TRIGLYCERIDE,CAPRYLYL GLYCOL,ETHYLHEXYLGLYCERIN,DIMER DILINOLEYL DIMER DILINOLEATE,+/- (MAY CONTAIN),MICA,TITANIUM DIOXIDE (CI 77891),IRON OXIDES (CI 77491),IRON OXIDES (CI 77492),IRON OXIDES (CI 77499),ALUMINUM POWDER (CI 77000),BISMUTH OXYCHLORIDE (CI 77163),BRONZE POWDER (CI 77400),CHROMIUM HYDROXIDE GREEN (CI 77289),CHROMIUM OXIDE GREENS (CI 77288),COPPER POWDER (CI 77400),FERRIC AMMONIUM FERROCYANIDE (CI 77510),FERRIC FERROCYANIDE (CI 77510),MANGANESE VIOLET (CI 77742),ULTRAMARINES (CI 77007),BLUE 1 LAKE (CI 42090),YELLOW 5 LAKE (CI 19140) | K2: BOÎTIER,RECHARGEABLE | L2: 11 g | M2: ITALIE | N2: 0887167661042 | O2: 1
A3: ALL HOURS - HYPER LUMINIZE - POUDRE ILLUMINATRICE VERSATILE | B3: YVES SAINT LAURENT | C3: L'ORÉAL | D3: ALL HOURS | E3: MAQUILLAGE | F3: VISAGE | G3: ENLUMINEUR,POUDRE | H3: TOUS TYPES DE PEAUX | I3: Appliquez All Hours Hyper Luminize sur les points saillants du visage : pommettes, arête du nez, arc de Cupidon et coin interne de l'œil. Estompez délicatement au doigt ou au pinceau. | J3: INCI TEINTE LUMINIZE 03 : SYNTHETIC FLUORPHLOGOPITE,C12-15 ALKYL BENZOATE,DIMETHICONE,CI 77891/TITANIUM DIOXIDE,MICA,CALCIUM ALUMINUM BOROSILICATE,TALC,HYDROGENATED POLYISOBUTENE,GLASS BEADS,BORON NITRIDE,MAGNESIUM STEARATE,CI 77491/IRON OXIDES,SILICA,HYDROGENATED STYRENE/BUTADIENE COPOLYMER,CAPRYLYL GLYCOL,NIACINAMIDE,SODIUM HYALURONATE,CAPRYLIC/CAPRIC TRIGLYCERIDE,SORBITAN ISOSTEARATE,ISODODECANE,METHICONE,CI 75470/CARMINE,TIN OXIDE,CITRUS LIMON PEEL EXTRACT/LEMON PEEL EXTRACT,TRIS-BHT MESITYLENE,TOCOPHEROL | K3: BOÎTIER | L3: 5 g | M3: FRANCE | N3: 3614274197044 | O3: 1
A4: BLUSH POUDRE | B4: LE ROUGE FRANÇAIS | C4: LE ROUGE FRANÇAIS | E4: MAQUILLAGE | F4: JOUES | G4: FARD À JOUES/BLUSH,POUDRE | H4: TOUTES CARNATIONS | I4: Le blush poudre s’applique après avoir préparé et unifié la base teint. À l’aide du pinceau kabuki intégré, prélevez une petite quantité de poudre en tapotant pour contrôler sa quantité. Retirez l’excédent et appliquez par mouvements circulaires sur les zones bombées de votre visage, comme les pommettes. Pour intensifier le résultat, répétez l’application par légères touches jusqu’à obtenir le fini souhaité, naturel ou sophistiqué. | J4: TALC,TAPIOCA STARCH*,CI 77007 (ULTRAMARINES),CI 77947 (ZINC OXIDE),KAOLIN,MICA,RUBIA TINCTORUM ROOT*,COCO-CAPRYLATE/CAPRATE,SQUALANE,GLYCERYL CAPRYLATE,BUTYROSPERMUM PARKII (SHEA) BUTTER*,SIMMONDSIA CHINENSIS (JOJOBA) SEED OIL*,ZINC STEARATE,TOCOPHEROL,ARGANIA SPINOSA KERNEL OIL*,GLYCERYL UNDECYLENATE,HELIANTHUS ANNUUS (SUNFLOWER) SEED OIL | K4: BOÎTIER | L4: 9 g | M4: FRANCE | O4: 1
A5: PROTOCOLE ANTI-IMPERFECTIONS - LE STOP-BOUTONS | B5: LIERAC | C5: LABORATOIRE NATIVE | D5: PROTOCOLE | E5: SOIN VISAGE | F5: VISAGE | G5: SOIN NUIT,POUDRE | H5: PEAUX NORMALES,PEAUX MIXTES À GRASSES,PEAUX MIXTES,PEAUX GRASSES | I5: Appliquer le soir. Ne pas agiter. Plonger un coton-tige dans le flacon jusqu'à la poudre puis appliquer sur les imperfections ciblées. Eviter le contour des yeux. Pour un protocole complet, utiliser en complément la ② Solution long terme : Le Peeling. | J5: ALCOHOL DENAT.,AQUA/WATER/EAU,ZINC OXIDE,CALAMINE,TALC,GLYCERIN,PROPANEDIOL,CI 77891/TITANIUM DIOXIDE,ZINC GLUCONATE,CAMPHOR,POTASSIUM AZELOYL DIGLYCINATE,SALICYLIC ACID,MENTHOL | K5: FLACON | L5: 15 ml | M5: FRANCE | N5: 3701436926229 | O5: 0
A6: LES TAROTS DE CHANEL - POUDRE BLUSH MATE | B6: CHANEL | C6: GROUPE CHANEL | D6: ÉDITION LIMITÉE 2024 | E6: MAQUILLAGE | F6: JOUES | G6: FARD À JOUES/BLUSH,POUDRE | H6: TOUTES CARNATIONS | I6: Appliquer la Création Exclusive LES TAROTS DE CHANEL sur les pommettes à l'aide du pinceau inclus pour apporter de la couleur au teint. Appliquer une touche légère pour un maquillage naturel. Ajouter une seconde touche pour intensifier le résultat. | J6: INCI TEINTE BLOOD ORANGE : SYNTHETIC FLUORPHLOGOPITE,ZINC STEARATE,SQUALANE,CAPRYLYL GLYCOL,ETHYLHEXYLGLYCERIN,ALUMINUM HYDROXIDE,AQUA (WATER),ALCOHOL,GLYCERIN,TOCOPHEROL,POLYSORBATE 80,+/- (MAY CONTAIN),CI 12085 (RED 36),CI 15850 (RED 6),CI 15850 (RED 7 LAKE),CI 15880 (RED 34),CI 15985 (YELLOW 6 LAKE),CI 17200 (RED 33 LAKE),CI 19140 (YELLOW 5 LAKE),CI 42090 (BLUE 1 LAKE),CI 42090 (BLUE 1),CI 45380 (RED 22 LAKE),CI 45410 (RED 28 LAKE),CI 45410 (RED 28),CI 73360 (RED 30 LAKE),CI 77007 (ULTRAMARINES),CI 77163 (BISMUTH OXYCHLORIDE),CI 77491, CI 77492, CI 77499 (IRON OXIDES),CI 77510 (FERRIC FERROCYANIDE),CI 77742 (MANGANESE VIOLET),CI 77891 (TITANIUM DIOXIDE),MICA | K6: BOÎTIER | L6: 14 g | M6: ITALIE | N6: 3145891517286 | O6: 1
A7: TEINT IDOLE ULTRA WEAR - C.E. SKIN TRANSFORMING HIGHLIGHTER | B7: LANCÔME | C7: L'ORÉAL | D7: TEINT IDOLE ULTRA WEAR | E7: MAQUILLAGE | F7: VISAGE | G7: ENLUMINEUR,POUDRE | H7: TOUS TYPES DE PEAUX,TOUTES CARNATIONS | I7: Appliquer Advance Génifique et masser vers le haut du visage pour une peau instantanément hydratée. Appliquer le fond de teint Teint Idole Ultra Wear pour une couverture parfaite. Appliquer ensuite un correcteur pour un effet lumineux et lifté. Bronzez instantanément votre peau avec le nouveau Teint Idole Ultra Wear C.E. Skin Transforming Bronzer. Utilisez un pinceau large et appliquez-le par mouvements circulaires là où le soleil se pose naturellement sur la peau (joues, nez, tempes et menton). Highlightez les zones naturelles de lumière avec le nouveau Teint Idole Ultra Wear C.E. Skin Transforming Highlighter. Utilisez un pinceau large et appliquez-le là où la lumière illumine votre visage (haut des joues, nez, menton). | J7: INCI TEINTE 01 LIGHT GLOW : TALC,CAPRYLIC/CAPRIC TRIGLYCERIDE,DIMETHICONE,ZINC STEARATE,SILICA,ZEA MAYS STARCH/CORN STARCH,PUNICA GRANATUM PERICARP EXTRACT,MORINGA OLEIFERA SEED OIL,ALARIA ESCULENTA EXTRACT,ISODODECANE,DIMETHICONE/VINYL DIMETHICONE CROSSPOLYMER,DIMETHICONOL,SILICA [NANO]/SILICA,TRIMETHYLSILOXYSILICATE,ASCORBYL TETRAISOPALMITATE,CAPRYLYL GLYCOL,ETHYLHEXYLGLYCERIN,TOCOPHEROL,POTASSIUM SORBATE,PARFUM/FRAGRANCE,LINALOOL,LIMONENE,+/- (MAY CONTAIN),MICA,CI 77491/IRON OXIDES,CI 77492/IRON OXIDES,CI 77499/IRON OXIDES,CI 77891/TITANIUM DIOXIDE | K7: BOÎTIER | L7: 10 g | M7: ITALIE | N7: 3614274110470 | O7: 1
A8: LES BEIGES - POUDRE BELLE MINE ENSOLEILLÉE 2024 | B8: CHANEL | C8: GROUPE CHANEL | E8: MAQUILLAGE | F8: VISAGE,COU,BUSTE/DÉCOLLETÉ | G8: ENLUMINEUR,POUDRE | H8: TOUTES CARNATIONS,TOUS TYPES DE PEAUX | I8: Pour une application simple et intuitive, prélever les trois poudres en un seul geste avec le PINCEAU POUDRE N°106. Appliquer sur les pommettes et à l’envi sur le front, les tempes, le nez et le menton pour réchauffer l’ensemble du visage. Pour une application plus structurée, utiliser le PINCEAU POUDRE N°106 pour appliquer les différents tons de LES BEIGES POUDRE BELLE MINE ENSOLEILLÉE. - Appliquer la poudre bronzante sur les pommettes en commençant par l'extérieur du visage et en terminant par le milieu de la joue, en effectuant des mouvements circulaires. Cette teinte peut également être appliquée sur le front, les tempes, le nez et le menton pour donner plus de chaleur à l'ensemble du visage. - Appliquer le blush en l’étirant des pommettes vers l’extérieur pour rehausser les pommettes. - Appliquer l’highlighter sur le haut des pommettes pour rehausser le teint et apporter une touche supplémentaire de lumière. | J8: INCI HARMONIE DEEP ROSE GOLD - POUDRE BRONZANTE : SYNTHETIC FLUORPHLOGOPITE,LAUROYL LYSINE,ZINC STEARATE,BORON NITRIDE,OCTYLDODECYL STEAROYL STEARATE,ZEA MAYS (CORN) STARCH,OCTYLDODECANOL,JASMINUM GRANDIFLORUM (JASMINE) FLOWER EXTRACT,1,2-HEXANEDIOL,CAPRYLYL GLYCOL,PARFUM (FRAGRANCE),ETHYLHEXYL PALMITATE,KAOLIN,TOCOPHERYL ACETATE,SILICA,+/- (MAY CONTAIN),CI 12085 (RED 36),CI 15850 (RED 6),CI 15850 (RED 7 LAKE),CI 15880 (RED 34),CI 15985 (YELLOW 6 LAKE),CI 17200 (RED 33 LAKE),CI 19140 (YELLOW 5 LAKE),CI 42090 (BLUE 1 LAKE),CI 45380 (RED 22 LAKE),CI 45410 (RED 28 LAKE),CI 73360 (RED 30 LAKE),CI 77007 (ULTRAMARINES),CI 77163 (BISMUTH OXYCHLORIDE),CI 77491, CI 77492, CI 77499 (IRON OXIDES),CI 77510 (FERRIC FERROCYANIDE),CI 77742 (MANGANESE VIOLET),CI 77891 (TITANIUM DIOXIDE),MICA | K8: BOÎTIER | L8: 15 g | M8: ITALIE | N8: 3145891863703 | O8: 1
A9: OMBRE ESSENTIELLE - OMBRE À PAUPIÈRES LONGUE TENUE MULTI-USAGE | B9: CHANEL | C9: GROUPE CHANEL | E9: MAQUILLAGE | F9: PAUPIÈRES | G9: FARD À PAUPIÈRES,COMPACT,POUDRE | H9: CONVIENT AUX PORTEURS DE LENTILLES | I9: Avec OMBRE ESSENTIELLE, affirmer son look en jouant sur 3 applications différentes, à porter seules ou en accumulation : - Ombrer l’intégralité des paupières d’une couleur intense et lumineuse. - Accentuer le regard d’un simple trait d’eye-liner aussi graphique que subtil. - Intensifier les sourcils d’une pointe de couleur audacieuse pour un look singulier. Humidifier légèrement le pinceau eye-liner biseauté afin d’obtenir un fini précis et une couleur intensifiée. | J9: INCI TEINTE 226 - ROUGE COSMOS : SYNTHETIC FLUORPHLOGOPITE,OCTYLDODECYL STEAROYL STEARATE,DIMETHICONE,POLYBUTENE,TRIMETHYLSILOXYSILICATE,CELLULOSE,HYDROGEN DIMETHICONE,CAPRYLYL GLYCOL,MAGNESIUM STEARATE,POTASSIUM SORBATE,SILICA,CHLORPHENESIN,TOCOPHERYL ACETATE,DIMETHICONE CROSSPOLYMER,SALVIA HISPANICA SEED OIL,TOCOPHEROL,+/- (MAY CONTAIN),CI 75470 (CARMINE),CI 77000 (ALUMINUM POWDER),CI 77007 (ULTRAMARINES),CI 77163 (BISMUTH OXYCHLORIDE),CI 77288 (CHROMIUM OXIDE GREENS),CI 77491, CI 77492, CI 77499 (IRON OXIDES),CI 77510 (FERRIC AMMONIUM FERROCYANIDE),CI 77510 (FERRIC FERROCYANIDE),CI 77742 (MANGANESE VIOLET),CI 77891 (TITANIUM DIOXIDE),MICA | K9: BOÎTIER | L9: 1,9 g | M9: FRANCE | N9: 3145891812268 | O9: 1
A10: MÉTÉORITES - PERLES DE POUDRE RÉVÉLATRICES DE LUMIÈRE - NOUVELLE FORMULE 2024 | B10: GUERLAIN | C10: LVMH | D10: MÉTÉORITES | E10: MAQUILLAGE | F10: VISAGE | G10: ENLUMINEUR,PERLES,POUDRE | H10: TOUTES CARNATIONS | I10: Utiliser le pinceau Météorites pour appliquer uniformément sur l’ensemble du visage, pour fixer le maquillage et améliorer sa tenue. Pour un éclat boosté, illuminer les parties bombées : dessiner un G du centre du front vers les tempes, les pommettes et le haut du nez en redescendant jusqu’à la pointe du menton. | J10: INCI TEINTE 04 AMBER/AMBRE : MICA,DISTARCH PHOSPHATE,SILICA,MAGNESIUM MYRISTATE,SYNTHETIC FLUORPHLOGOPITE,CELLULOSE,MAGNESIUM CARBONATE HYDROXIDE,CALCIUM SODIUM BOROSILICATE,HYDROXYPROPYL STARCH,CAPRYLYL GLYCOL,ETHYLHEXYLGLYCERIN,PARFUM (FRAGRANCE),SODIUM DEHYDROACETATE,CALCIUM ALUMINUM BOROSILICATE,SORBIC ACID,TIN OXIDE,TOCOPHEROL,+/- (MAY CONTAIN),CI 77891 (TITANIUM DIOXIDE),CI 77163 (BISMUTH OXYCHLORIDE),CI 77491, CI 77492, CI 77499 (IRON OXIDES),CI 77288 (CHROMIUM OXIDE GREENS),CI 73360 (RED 30 LAKE),CI 77007 (ULTRAMARINES) | K10: BOÎTIER | L10: 25 g | M10: FRANCE | N10: 3346470438781 | O10: 1
A11: THE POREfessional WOW POLISH | B11: BENEFIT | C11: LVMH | D11: THE POREfessional | E11: SOIN VISAGE | F11: VISAGE | G11: GOMMAGE,POUDRE | H11: TOUS TYPES DE PEAUX | I11: Saupoudrez dans la paume humide et frottez pour faire mousser. Massez sur le visage en évitant le contour des yeux, puis rincez. Utilisez 1 à 2 fois par semaine après le nettoyage. Mélangez avec la baguette Wow (incluse) pour préserver une poudre uniforme. | J11: SODIUM COCOYL ISETHIONATE,SODIUM METHYL COCOYL TAURATE,KAOLIN,TAPIOCA STARCH,SODIUM CHLORIDE,ZEA MAYS (CORN) STARCH,PERLITE,HYDROXYPROPYL METHYLCELLULOSE,SQUALANE,GLUCONOLACTONE,MICA,GLYCERYL CAPRYLATE,PENTYLENE GLYCOL,COCOS NUCIFERA (COCONUT) FRUIT EXTRACT,LACTIC ACID,CI 77742 (MANGANESE VIOLET),DEHYDROACETIC ACID,AQUA (WATER),DIMETHICONE,BISABOLOL,GLYCERYL UNDECYLENATE,PARFUM (FRAGRANCE),MALTODEXTRIN,SODIUM GLUCONATE,COCAMIDOPROPYL BETAINE,AVENA SATIVA (OAT) KERNEL FLOUR,FARNESOL,CI 42090 (BLUE 1 LAKE),CI 19140 (YELLOW 5 LAKE),PENTAERYTHRITYL TETRA-DI-T-BUTYL HYDROXYHYDROCINNAMATE,TOCOPHEROL | K11: FLACON | L11: 45 g | N11: 0602004153746 | O11: 0
A12: ARTIST EYESHADOW - NOUVELLE FORMULE 2024 | B12: MAKE UP FOR EVER | C12: LVMH | E12: MAQUILLAGE | F12: PAUPIÈRES | G12: FARD À PAUPIÈRES,POUDRE | H12: TOUTES CARNATIONS | I12: 1/ Prélever la matière avec le côté plat du pinceau #248. 2/ Appliquer l'ombre à paupières sur la zone souhaitée en tapotant délicatement puis en effectuant des mouvements de balayage avec la partie plate du pinceau. 3/ Avec le côté rond du pinceau #248, estomper avec de petits mouvements circulaires, puis d'avant en arrière. | J12: INCI TEINTE 100 - WHATEVER BLACK : SYNTHETIC FLUORPHLOGOPITE,DIMETHICONE,ZINC STEARATE,CAPRYLYL GLYCOL,PENTYLENE GLYCOL,ETHYLHEXYLGLYCERIN,SILICA,DIISOSTEARYL MALATE,OCTYLDODECYL STEAROYL STEARATE,SODIUM DEHYDROACETATE,KAOLIN,TOCOPHERYL ACETATE,SORBITAN SESQUIOLEATE,TOCOPHEROL,+/- (MAY CONTAIN),CI 77499 (IRON OXIDES),CI 77266 [NANO] (BLACK 2),CI 77007 (ULTRAMARINES) | K12: BOÎTIER | L12: 5 g | O12: 1
A13: POUDRE-MOUSSE NETTOYANTE | B13: COTTAN | C13: Beauty Brands Studio | E13: SOIN VISAGE | F13: VISAGE | G13: DÉMAQUILLANT/NETTOYANT,POUDRE | H13: TOUS TYPES DE PEAUX,CONVIENT AUX PEAUX SENSIBLES/RÉACTIVES | I13: Déposez de la poudre et de l'eau dans le creux de votre main, puis frictionnez afin d'obtenir une mousse à appliquer sur votre visage. Lavez votre visage à votre habitude avant de rincer abondamment. Évitez le contact avec les yeux. | J13: ZEA MAYS STARCH,DISODIUM COCOYL GLUTAMATE,SODIUM COCOYL GLUTAMATE,ORYZA SATIVA (RICE) POWDER,PARFUM (FRAGRANCE),PAEONIA OFFICINALIS ROOT EXTRACT | K13: FLACON SALIÈRE | L13: 30 g | M13: FRANCE | N13: 3760262407050 | O13: 0
A14: ALWAYS FABULOUS - FOND DE TEINT POUDRE SPF 20 | B14: BOURJOIS | C14: COTY GROUP INC | D14: ALWAYS FABULOUS | E14: MAQUILLAGE | F14: VISAGE | G14: FOND DE TEINT,POUDRE | H14: TOUS TYPES DE PEAUX,TOUTES CARNATIONS | I14: Appliquez d'abord la poudre matifiante sur la zone T, puis sur l'ensemble du visage si nécessaire, pour un teint matifié. | J14: MICA,ZINC OXIDE,KAOLIN,ZINC STEARATE,DIMETHICONE,BUTYLOCTYL SALICYLATE,BORON NITRIDE,TRIMETHYLSILOXYSILICATE,SACCHAROMYCES FERMENT,SILICA,TRIETHOXYCAPRYLYLSILANE,1,2-HEXANEDIOL,CAPRYLYL GLYCOL,SODIUM BENZOATE,METHICONE,ALUMINA,LAUROYL LYSINE,PARFUM/FRAGRANCE,SODIUM HYALURONATE,HYDROGEN DIMETHICONE,DIMETHYLMETHOXY CHROMANOL,BENZYL SALICYLATE,+/- (MAY CONTAIN),TITANIUM DIOXIDE (CI 77891),IRON OXIDES (CI 77491, CI 77492, CI 77499) | K14: BOÎTIER | L14: 10 g | O14: 1
A15: OMBRE D'HERMÈS - PALETTE DE COULEURS QUATUOR OMBRES POUR LES YEUX | B15: HERMÈS | C15: HERMÈS INTERNATIONAL | D15: LE REGARD | E15: MAQUILLAGE | F15: PAUPIÈRES | G15: FARD À PAUPIÈRES,POUDRE | H15: TOUS TYPES DE PEAUX | I15: Appliquer et estomper sur les paupières à l'aide de votre pinceau préféré. Si vous le souhaitez, mouillez légèrement le pinceau avant l'application pour amplifier l'intensité et la précision de la couleur. | J15: OMBRES MORDORÉES - LIGHT ACCENT & NEUTRAL BASE (IRISÉ/IRIDESCENT) INGREDIENTS : MICA,CALCIUM SODIUM BOROSILICATE,CAPRYLIC/CAPRIC TRIGLYCERIDE,OCTYLDODECYL STEAROYL STEARATE,ZINC STEARATE,METHYLPROPANEDIOL,PHENOXYETHANOL,CAPRYLYL GLYCOL,SODIUM DEHYDROACETATE,TIN OXIDE,PHENYLPROPANOL,CELLULOSE,MAGNESIUM STEARATE,MORUS ALBA BARK EXTRACT,+/- (MAY CONTAIN),CI 77891 (TITANIUM DIOXIDE),CI 77163 (BISMUTH OXYCHLORIDE),CI 77492/CI 77491/CI 77499 (IRON OXIDES),CI 19140 (YELLOW 5 LAKE) | K15: BOÎTIER,RECHARGEABLE | L15: 3 g | M15: ITALIE | N15: 3346130411314 | O15: 1
A16: SKIN PROUD - GLOW DUST - EXFOLIATING POWDER CLEANSER | B16: I AM PROUD | C16: LOTTIE LONDON LIMITED | D16: SKIN PROUD | E16: SOIN VISAGE | F16: VISAGE | G16: DÉMAQUILLANT/NETTOYANT,POUDRE | H16: TOUS TYPES DE PEAUX | I16: Pour half a teaspoon of powder into wet hands, add a small amount of water and rub together to create a milky lather. Massage into face, avoiding the eye area, and rinse off. Use 2-3 times a week. Top Tip: combine with your cleanser to add extra exfoliation. | J16: MANNITOL,MICROCRYSTALLINE CELLULOSE,SODIUM COCOYL ISETHIONATE,3-O-ETHYL ASCORBIC ACID,BUTYLENE GLYCOL,CELLULOSE GUM,LEUCONOSTOC/RADISH ROOT FERMENT FILTRATE,PEG-40 HYDROGENATED CASTOR OIL,COCONUT ACID,BROMELAIN,CAMELLIA SINENSIS LEAF EXTRACT,HYDROXYPROPYL METHYLCELLULOSE,AQUA (WATER, EAU),MORINGA OLEIFERA SEED EXTRACT,SODIUM ISETHIONATE,GLUCONOLACTONE,SIMMONDSIA CHINENSIS (JOJOBA) SEED OIL,TOCOPHERYL ACETATE,MACADAMIA INTEGRIFOLIA SEED OIL,GLYCINE SOJA (SOYBEAN) OIL,GLYCERIN,FERULIC ACID,1,6-HEXAMETHYLENE DIISOCYANATE,GLYCYRRHIZA GLABRA (LICORICE) ROOT EXTRACT,PHENOXYETHANOL,POTASSIUM SORBATE,SODIUM BENZOATE,DISODIUM PHOSPHATE,CITRIC ACID,TOCOPHEROL | K16: FLACON SALIÈRE,CAPSULE SERVICE | L16: 40 g | M16: AUSTRALIE | N16: 5056183607869 | O16: 0
A17: BOUQUET FLORAL - POUDRE EXFOLIANTE DOUCEUR | B17: MELVITA | C17: GROUPE L'OCCITANE | D17: BOUQUET FLORAL | E17: SOIN VISAGE | F17: VISAGE | G17: GOMMAGE,POUDRE,ANHYDRE | H17: TOUS TYPES DE PEAUX | I17: Melvita recommande d'utiliser sa poudre exfoliante douceur à raison de 2 fois par semaine, de préférence le soir. Mélangez dans la main humide 1 cuillère à café de poudre puis 1 cuillère à café d'eau. Massez ce mélange sur le visage préalablement mouillé, en évitant la zone du contour des yeux, et rincez abondamment. Pour une exfoliation plus intense, laissez poser 30 à 60 secondes. | J17: ZEA MAYS (CORN) STARCH*,GLUCOSE,SODIUM COCOYL GLUTAMATE,LACTOBACILLUS/PUNICA GRANATUM FRUIT FERMENT EXTRACT,HIBISCUS SABDARIFFA FLOWER EXTRACT,MALTODEXTRIN,CAMELLIA SINENSIS LEAF EXTRACT,HYDROLYZED GARDENIA FLORIDA EXTRACT,MAGNESIUM HYDROXIDE,PARFUM/FRAGRANCE,LINALOOL,LIMONENE,CITRONELLOL,GERANIOL | K17: FLACON,CAPSULE SERVICE | L17: 30 g | M17: FRANCE | N17: 3284410049812 | O17: 0
A18: POUDRE DE LAIT EXFOLIANTE | B18: EMBRYOLISSE | C18: LABORATOIRES EMBRYOLISSE | E18: SOIN VISAGE | F18: VISAGE | G18: GOMMAGE,POUDRE,LAIT | H18: TOUS TYPES DE PEAUX | I18: Pour une exfoliation moussante : Mélanger dans le creux de la main une petite quantité de poudre et quelques gouttes d'eau, masser le visage puis rincer à l'eau. 2 ou 3 fois par semaine. Eviter le contact avec les yeux. En cas de contact, rincer abondamment à l'eau claire. Vous pouvez également associer la Poudre de Lait Exfoliante à d’autres soins Embryolisse, comme le Lait-Crème Concentré ou l'Eau Active, pour une utilisation personnalisée qui répond aux besoins de chaque peau. | J18: ORYZA SATIVA (RICE) STARCH,ZEA MAYS (CORN) STARCH,SODIUM LAUROYL GLUTAMATE,COCOS NUCIFERA FRUIT POWDER,COCOS NUCIFERA (COCONUT) SHELL POWDER,CITRIC ACID,CALCIUM CARBONATE,SODIUM BICARBONATE,MALTODEXTRIN,PARFUM (FRAGRANCE),COCOS NUCIFERA (COCONUT) FRUIT EXTRACT | K18: FLACON,CAPSULE SERVICE | L18: 40 g | M18: FRANCE | N18: 3350900002572 | O18: 0
A19: GOOF PROOF BROW POWDER - EASY BROW FILLING POWDER | B19: BENEFIT | C19: LVMH | E19: MAQUILLAGE | F19: SOURCILS | G19: POUDRE,COMPACT | I19: Apply with an angled brush to outline brows, shape and define. Use light strokes to fill in sparse brow areas and layer to build color. Blend with spoolie. | J19: 4 WARM DEEP BROWN INGREDIENTS LISTING : MICA,SYNTHETIC FLUORPHLOGOPITE,DIMETHICONE,TRIMETHYLSILOXYSILICATE,MICROCRYSTALLINE CELLULOSE,KAOLIN,MAGNESIUM STEARATE,TRIETHOXYCAPRYLYLSILANE,MAGNESIUM MYRISTATE,RICINUS COMMUNIS (CASTOR) SEED OIL,PHENOXYETHANOL,SORBIC ACID,CAPRYLYL GLYCOL,TOCOPHEROL,HELIANTHUS ANNUUS (SUNFLOWER) SEED OIL,+/- (MAY CONTAIN),CI 77491, CI 77492, CI 77499 (IRON OXIDES),CI 77891 (TITANIUM DIOXIDE),CI 19140 (YELLOW 5 LAKE),CI 42090 (BLUE 1 LAKE),CI 77007 (ULTRAMARINES),CI 77742 (MANGANESE VIOLET) | K19: BOÎTIER | L19: 1,9 g | M19: FRANCE | N19: 0602004140357 | O19: 1
A20: SKIN PERFECTO - CRÈME COMPACTE SPF 30/PA++ - NOUVELLE FORMULE 2023 | B20: GIVENCHY | C20: LVMH | D20: SKIN PERFECTO | E20: MAQUILLAGE | F20: VISAGE | G20: SOIN,CRÈME/ÉMULSION,COMPACT | H20: TOUS TYPES DE PEAUX | I20: Utilisez la Crème Compacte à la place de votre crème habituelle, après le Sérum Éclat Multi-Vitaminé Skin Perfecto ou en retouches à tout moment de la journée pour donner un boost d'éclat à votre peau. ÉTAPE 1 Prélevez délicatement la crème avec l'applicateur. ÉTAPE 2 Lissez sur l'ensemble du visage en effectuant des mouvements ascendants. ÉTAPE 3 Répartissez uniformément en pressant jusqu'à absorption. ÉTAPE 4 Retouchez tout au long de la journée en tapotant légèrement pour une touche d'éclat instantanée. LE CONSEIL PROFESSIONNEL Appliquez une deuxième couche de crème compacte à l'endroit où vous appliqueriez votre highlighter (pommettes). | J20: AQUA (WATER),DIBUTYL ADIPATE,GLYCERIN,ZINC OXIDE,DICAPRYLYL CARBONATE,CANDELILLA CERA (EUPHORBIA CERIFERA (CANDELILLA) WAX),BUTYLENE GLYCOL,ETHYLHEXYL SALICYLATE,PHENYL TRIMETHICONE,DIMETHICONE,BIS-ETHYLHEXYLOXYPHENOL METHOXYPHENYL TRIAZINE,ETHYLHEXYL TRIAZONE,MICA,CI 77891 (TITANIUM DIOXIDE),CETYL PEG/PPG-10/1 DIMETHICONE,CERA CARNAUBA (COPERNICA CERIFERA (CARNAUBA) WAX),SYNTHETIC FLUORPHLOGOPITE,C30-45 ALKYL METHICONE,C30-45 OLEFIN,CAPRYLYL GLYCOL,MYRISTYL MYRISTATE,SORBITAN SESQUIOLEATE,ETHYLHEXYLGLYCERIN,PARFUM (FRAGRANCE),DIMETHICONE/PEG-10/15 CROSSPOLYMER,ASCORBYL GLUCOSIDE,HYDROXYACETOPHENONE,CHLORPHENESIN,TOCOPHERYL ACETATE,SILICA,CITRUS PARADISI (GRAPEFRUIT) FRUIT EXTRACT,TRIETHOXYCAPRYLYLSILANE,SCHINUS TEREBINTHIFOLIUS SEED EXTRACT,XANTHAN GUM,HYDROGEN DIMETHICONE,CITRIC ACID,CI 77491 (IRON OXIDES),DIPROPYLENE GLYCOL,SODIUM CITRATE,TOCOPHEROL,PENTAERYTHRITYL TETRA-DI-T-BUTYL HYDROXYHYDROCINNAMATE | K20: BOÎTIER | L20: 12 g | M20: FRANCE | N20: 3274872444249 | O20: 0
A21: REUSABLE FOAMING CLEANSER STARTER KIT, BOTTLE & REFILL PACK | B21: NEUTROGENA | C21: JOHNSON & JOHNSON | E21: SOIN VISAGE | F21: VISAGE | G21: DÉMAQUILLANT/NETTOYANT,POUDRE | H21: TOUS TYPES DE PEAUX,CONVIENT AUX PEAUX SENSIBLES/RÉACTIVES | I21: DIRECTION TO MIX: FILL UP Remove pump. Fill the bottle to the indented fill line with 7.5 fl oz (221 mL) of warm, drinking quality water. POUR IN Cut open the packet along the dotted line and insert the mouth of it into the bottle (avoiding contact with water). To minimize dust, tap gently to empty the packet. Reattach pump. SHAKE Shake bottle for 10 seconds and wait for 1 minute before the first use. When finished, wash bottle according to carton instructions and fill with another concentrate refill! DIRECTION FOR USE: Wet face. Pump cleanser into hands. Massage face gently. Rinse. No need to shake. | J21: SODIUM METHYL COCOYL TAURATE,SODIUM COCOYL ISETHIONATE,SODIUM BENZOATE,MAGNESIUM SULFATE,CITRIC ACID,DISODIUM EDTA,ASCORBIC ACID | K21: EMBALLAGE SACHET/CARTON,FLACON MOUSSEUR,RECHARGEABLE | L21: 221 ml | M21: CANADA | O21: 0
A22: TERRACOTTA LUMINIZER - LA POUDRE ENLUMINEUR | B22: GUERLAIN | C22: LVMH | D22: TERRACOTTA | E22: MAQUILLAGE | F22: VISAGE | G22: ENLUMINEUR,POUDRE | H22: TOUTES CARNATIONS | I22: La poudre enlumineur Terracotta Luminizer peut s’utiliser sur le fond de teint ou la peau nue. Appliquer en touches sur le haut des pommettes, l’arête du nez et l’arc de Cupidon, pour un maquillage sensuel, éclatant et scintillant. Étirer sous l’arcade sourcilière, ou en ombre à paupières, pour un regard subtilement illuminé. | J22: MICA,CAPRYLIC/CAPRIC TRIGLYCERIDE,SILICA,ALUMINA,C13-15 ALKANE,COCO-CAPRYLATE/CAPRATE,POLYGLYCERYL-3 POLYRICINOLEATE,POLYGLYCERYL-4 CAPRATE,BUTYLENE GLYCOL,TRIHEPTANOIN,GLYCERIN,C9-12 ALKANE,PARFUM (FRAGRANCE),DILINOLEIC ACID/BUTANEDIOL COPOLYMER,CAPRYLYL GLYCOL,ETHYLHEXYLGLYCERIN,TRIETHOXYCAPRYLYLSILANE,1,2-HEXANEDIOL,LAUROYL LYSINE,POLYGLYCERYL-3 DIISOSTEARATE,GELLAN GUM,CALCIUM CHLORIDE,CASTOR OIL/IPDI COPOLYMER,ARGANIA SPINOSA KERNEL OIL,TOCOPHEROL,+/- (MAY CONTAIN),CI 77891 (TITANIUM DIOXIDE),CI 77163 (BISMUTH OXYCHLORIDE),CI 77491, CI 77492 (IRON OXIDES) | K22: BOÎTIER | L22: 7 g | M22: FRANCE | N22: 3346470435667 | O22: 1
A23: RARE EARTH DEEP PORE-MINIMIZING & POLISHING POWDER CLEANSER | B23: KIEHL'S | C23: L'ORÉAL | E23: SOIN VISAGE | F23: VISAGE | G23: DÉMAQUILLANT/NETTOYANT,POUDRE | H23: PEAUX NORMALES À GRASSES,PEAUX NORMALES,PEAUX GRASSES | I23: Gently shake before use. For use as a daily cleanser, apply a dime sized amount directly onto wet hands and work into a light foam, then apply onto damp facial skin in circular motions. Rinse thoroughly with water. Recommended as a daily cleanser twice a day. For a more intensive facial scrub, apply just a few drops of water to a dime sized amount of the powder cleanser to create a thicker paste. Rinse thoroughly with water after use. Recommended as a facial scrub 1–2 times a week. Explore our other pore minimizing formulas like our purifying clay mask, pore minimizing cleanser and pore minimizing toner. | J23: ZEA MAYS STARCH/CORN STARCH,DISODIUM LAURYL SULFOSUCCINATE,SODIUM LAUROYL GLUTAMATE,POTASSIUM COCOYL GLYCINATE,KAOLIN,POTASSIUM CHLORIDE,CELLULOSE,MICROCRYSTALLINE CELLULOSE,PERLITE,ALUMINUM STARCH OCTENYLSUCCINATE,MAGNESIUM STEARATE,TARTARIC ACID,AQUA/WATER,COCAMIDOPROPYL BETAINE,ALOE BARBADENSIS LEAF JUICE POWDER,ALLANTOIN,SODIUM CHLORIDE | K23: FLACON,CAPSULE SERVICE | L23: 100 g | M23: USA | N23: 3605972787231 | O23: 0
A24: HD SKIN - POWDER FOUNDATION - FOND DE TEINT POUDRE FLOUTTEUR IMPERCEPTIBLE 24H | B24: MAKE UP FOR EVER | C24: LVMH | D24: HD SKIN | E24: MAQUILLAGE | F24: VISAGE | G24: FOND DE TEINT,POUDRE,COMPACT | H24: TOUS TYPES DE PEAUX,TOUTES CARNATIONS | I24: Pour un véritable effet seconde peau : utilisez le HD SKIN POWDER FOUNDATION seul comme un fond de teint poudre en choisissant l'une de ces 2 alternatives : 1. Appliquez avec le côté doux de l'éponge, du centre du visage vers l'extérieur en tamponnant. 2. Pour un look plus naturel, appliquez le fond de teint avec l'autre côté de l'éponge, en étalant la matière. Pour un fini plus naturel ou une retouche : utilisez le pinceau n°128 sur l'ensemble du visage. Conseils de pro : 1. Il peut être utilisé en tant que primer sur les paupières grasses. 2. Il peut être utilisé pour les retouches avec le pinceau #128 pour estomper et couvrir uniquement les endroits nécessaires. 3. Il peut être utilisé avec un pinceau par dessus un fond de teint liquide pour fixer votre maquillage. | J24: INCI TEINTE CLAIRE - NUDE - BEIGE SOUS TON NEUTRE 2N22 : SYNTHETIC FLUORPHLOGOPITE,BORON NITRIDE,PENTAERYTHRITYL TETRAISOSTEARATE,SILICA,POLYMETHYL METHACRYLATE,ALUMINA,ZINC LAURATE,METHICONE,DIMETHICONE,CAPRYLYL GLYCOL,ETHYLHEXYLGLYCERIN,SODIUM DEHYDROACETATE,ALUMINUM HYDROXIDE,HYDROGEN DIMETHICONE,TOCOPHEROL,+/- (MAY CONTAIN),CI 77491, CI 77492, CI 77499 (IRON OXIDES),CI 77891 (TITANIUM DIOXIDE),CI 77163 (BISMUTH OXYCHLORIDE) | K24: BOÎTIER | L24: 11 g | M24: FRANCE | O24: 1
A25: FOND DE TEINT POUDRE SOIN SPF | B25: AIME | C25: AIME INC. SAS | E25: MAQUILLAGE | F25: VISAGE | G25: FOND DE TEINT,POUDRE | H25: TOUTES CARNATIONS,TOUS TYPES DE PEAUX,CONVIENT AUX PEAUX SENSIBLES/RÉACTIVES | I25: Appliquez votre Fond de Teint Poudre Soin sur une peau sèche et hydratée avec notre Pinceau Visage en réalisant des mouvements circulaires depuis le centre du visage. Répétez selon la couvrance souhaitée. | J25: MICA,ZINC STEARATE,TITANIUM DIOXIDE,LAUROYL LYSINE,SILICA,BORON NITRIDE,COCO-CAPRYLATE/CAPRATE,KAOLIN,OCTYLDODECYL STEAROYL STEARATE,OCTYLDODECYL PCA,CETYL ALCOHOL,TOCOPHERYL ACETATE,GLYCERYL CAPRYLATE,PENTYLENE GLYCOL,TIN OXIDE,SQUALANE,BISABOLOL,MAGNOLIA OFFICINALIS BARK EXTRACT,RICINUS COMMUNIS SEED OIL,HYDROLYZED SODIUM HYALURONATE,ALPHA-GLUCAN OLIGOSACCHARIDE,SODIUM HYALURONATE,HYDROGENATED CASTOR OIL,ZINGIBER OFFICINALE ROOT EXTRACT,+/- (MAY CONTAIN),CI 77891 (TITANIUM DIOXIDE),CI 19140 (YELLOW 5 LAKE),CI 77491 (IRON OXIDES),CI 77492 (IRON OXIDES),CI 77499 (IRON OXIDES) | K25: BOÎTIER | L25: 7 g | M25: FRANCE | O25: 1
A26: PURE C INTENSIVE TREATMENT - 800 MG VITAMIN C + 1,25% HA4 HYALURONIC ACID | B26: FaceD | C26: HCS | high cosmetic solution s.r.l. | E26: SOIN VISAGE | F26: VISAGE | G26: SOIN,FLUIDE/LIQUIDE,POUDRE | H26: TOUS TYPES DE PEAUX,CONVIENT AUX PEAUX SENSIBLES/RÉACTIVES | I26: Activate the treatment by pressing the tank cap containing vitamin C, so that it is released into the bottle. Shake the bottle vigorously for a few seconds to dissolve the vitamin C. Replace the cap with the reusable dropper. | J26: AQUA (WATER),ASCORBIC ACID,GLYCERIN,NIACINAMIDE,SODIUM HYALURONATE,PANTHENOL,SODIUM HYALURONATE CROSSPOLYMER,HYALURONIC ACID,PENTYLENE GLYCOL,DISODIUM EDTA,PHENOXYETHANOL,ETHYLHEXYLGLYCERIN | K26: FLACON,PIPETTE | L26: 4 x 4 ml | M26: ITALIE | O26: 0
A27: MY CLARINS CLEAR-OUT - LOTION CIBLÉE IMPERFECTIONS | B27: CLARINS | C27: GROUPE CLARINS | D27: MY CLARINS | E27: SOIN VISAGE | F27: VISAGE | G27: SOIN,LOTION,BI-PHASE,POUDRE | H27: TOUS TYPES DE PEAUX | I27: Insérez un coton tige directement dans la solution, sans la mélanger, afin de prélever un peu de poudre qui contient les actifs pour lutter contre les imperfections et appliquez-la sur le(s) bouton(s). | J27: AQUA/WATER/EAU,ALCOHOL,CI 77947/ZINC OXIDE,ISOPROPYL ALCOHOL,VACCINIUM MYRTILLUS FRUIT EXTRACT,GLYCERIN,SALICYLIC ACID,SACCHARUM OFFICINARUM (SUGAR CANE) EXTRACT,ZINC GLUCONATE,BUTYLENE GLYCOL,CITRUS AURANTIUM DULCIS (ORANGE) FRUIT EXTRACT,CITRUS LIMON (LEMON) FRUIT EXTRACT,SODIUM HYDROXIDE,T-BUTYL ALCOHOL,ACER SACCHARUM (SUGAR MAPLE) EXTRACT,SPIRAEA ULMARIA EXTRACT,DENATONIUM BENZOATE,CI 14700/RED 4 | K27: FLACON | L27: 13 ml | M27: FRANCE | N27: 3666057078415 | O27: 0
A28: MASQUE EXFOLIANT ENZYMATIQUE | B28: SISLEY | C28: GROUPE SISLEY | E28: SOIN VISAGE | F28: VISAGE | G28: MASQUE,PEELING,POUDRE | H28: TOUS TYPES DE PEAUX,CONVIENT AUX PEAUX SENSIBLES/RÉACTIVES | I28: Déposer l’équivalent d’une cuillère à café de poudre au creux de la main et mélanger du bout des doigts avec une petite quantité d’eau jusqu’à l’obtention d’une crème moussante. Appliquer en couche fine sur l’ensemble du visage et du cou, en évitant le contour des yeux. Laisser poser 1 minute maximum, puis rincer soigneusement à l’eau. Eviter le contact avec les yeux. Poursuivre par l’application du rituel de soins quotidiens suivants. | J28: HYDROXYPROPYL STARCH PHOSPHATE,CELLULOSE,SODIUM COCOYL GLYCINATE,AQUA/WATER/EAU,SILICA,SODIUM METHYL COCOYL TAURATE,NIACINAMIDE,MALTODEXTRIN,TITANIUM DIOXIDE (CI 77891),XANTHAN GUM,PAPAIN,LAVANDULA ANGUSTIFOLIA (LAVENDER) OIL,THYMUS MASTICHINA FLOWER OIL,SODIUM SURFACTIN,GUAR HYDROXYPROPYLTRIMONIUM CHLORIDE,HYDROGENATED LECITHIN,LINALOOL,LIMONENE | K28: FLACON,CAPSULE SERVICE | L28: 40 g | M28: FRANCE | N28: 3473311524355 | O28: 0
A29: RETINOL FAST RELEASE WRINKLE-REDUCING NIGHT SERUM | B29: KIEHL'S | C29: L'ORÉAL | D29: DERMATOLOGIST SOLUTIONS | E29: SOIN VISAGE | F29: VISAGE | G29: SOIN NUIT,SÉRUM,POUDRE | H29: TOUS TYPES DE PEAUX | I29: Pour l'activer : - Retournez le flacon, retirez le bouchon inférieur et mettez-le de côté. - Ouvrez la pochette, faites tourner la capsule de rétinol sur le fond du flacon. - Appuyez sur le bouton de la capsule pour libérer la poudre de rétinol pur. - Secouez vigoureusement pour que le produit soit entièrement mélangé au sérum. - Retirez et jetez la capsule, remplacez-la par le bouchon d'origine. Appliquer : - Appliquez une fois par jour, le soir. - Appuyez sur le bouton noir 2 à 3 fois pour obtenir une goutte de la taille d'un petit pois. - Appliquez délicatement sur une peau propre et sèche. - Complétez votre routine de soins de nuit avec notre crème anti-âge pour des bienfaits optimaux sur la jeunesse de votre peau. Le matin, utilisez notre correcteur de taches brunes et notre écran solaire pour le visage avec FPS 50 pour une peau plus claire. | J29: AQUA/WATER,GLYCERIN,PROPANEDIOL,BUTYLENE GLYCOL,GLYCERETH-26,PANTHENOL,1,2-HEXANEDIOL,POLYGLYCERIN-3,C12-14 PARETH-12,PHENOXYETHANOL,CAPRYLYL GLYCOL,AMMONIUM ACRYLOYLDIMETHYLTAURATE/VP COPOLYMER,BETAINE,XANTHAN GUM,ETHYLHEXYLGLYCERIN,ADENOSINE,CARBOMER,GLYCERYL ACRYLATE/ACRYLIC ACID COPOLYMER,TROMETHAMINE,GLYCERETH-25 PCA ISOSTEARATE,T-BUTYL ALCOHOL,TOCOPHEROL | K29: FLACON,EMBALLAGE SACHET/CARTON | L29: 28 ml|1 g | M29: CORÉE | O29: 0
A30: TERRACOTTA BLOOMING BEE - LA POUDRE ÉCLAT BONNE MINE - ÉDITION LIMITÉE | B30: GUERLAIN | C30: LVMH | D30: TERRACOTTA - ÉDITION LIMITÉE | E30: MAQUILLAGE | F30: VISAGE,COU | G30: ENLUMINEUR,POUDRE | H30: TOUTES CARNATIONS | I30: LE MOT DE VIOLETTE, DIRECTRICE DE LA CRÉATION DU MAQUILLAGE GUERLAIN : « MON SECRET POUR UN EFFET SUN-KISSED IRRÉSISTIBLE ? APPLIQUER LA TERRACOTTA SUR LES ZONES LES PLUS BOMBÉES COMME LES POMMETTES, L’ARÊTE DU NEZ ET LE HAUT DU FRONT POUR APPORTER PLUS DE STRUCTURE AU VISAGE TOUT EN RÉCHAUFFANT DÉLICATEMENT LE TEINT. » | J30: MICA,SILICA,LAUROYL LYSINE,ZINC STEARATE,BIS-BEHENYL/ISOSTEARYL/PHYTOSTERYL DIMER DILINOLEYL DIMER DILINOLEATE,OCTYLDODECYL STEAROYL STEARATE,DICAPRYLYL ETHER,CELLULOSE,CALCIUM SODIUM BOROSILICATE,DIMER DILINOLEYL DIMER DILINOLEATE,PARFUM (FRAGRANCE),CAPRYLYL GLYCOL,ETHYLHEXYLGLYCERIN,SODIUM DEHYDROACETATE,PENTYLENE GLYCOL,AQUA (WATER),BUTYLENE GLYCOL,PROPANEDIOL,MEL (HONEY),GLYCERIN,TOCOPHEROL,BUTYROSPERMUM PARKII SEEDCAKE EXTRACT,TIN OXIDE,+/- (MAY CONTAIN),CI 77891 (TITANIUM DIOXIDE),CI 77163 (BISMUTH OXYCHLORIDE),CI 77491, CI 77492, CI 77499 (IRON OXIDES),CI 73360 (RED 30 LAKE) | K30: BOÎTIER | L30: 10 g | M30: FRANCE | O30: 1
A31: PROBIOTIC EXFOLIATING POWDER FACE + SCALP | B31: BOSCIA | C31: boscia LLC | E31: CAPILLAIRE,SOIN VISAGE | F31: VISAGE,CUIR CHEVELU | G31: GOMMAGE,POUDRE | H31: TOUS TYPES DE CHEVEUX,CONVIENT AUX CHEVEUX COLORÉS | I31: Use up to 4x a week, or as needed. Face - Start with wet hands and face. Work a dime-sized amount of powder into hands to create a lather. Apply and gently massage face in a circular motion for 10 to 20 seconds. Scalp - Start with wet, unwashed hair. Work a quarter-sized amount of powder into wet hands to create a lather. Slide through hair using fingertips to massage into scalp. Leave on scalp for 3-5 minutes for further relief. Rinse and follow with shampoo/conditioner, as needed. Warning: For external use only. Use only as directed. Avoid contact with eyes. | J31: TAPIOCA STARCH,SODIUM COCOYL ISETHIONATE,ILLITE,SODIUM LAUROYL GLUTAMATE,POTASSIUM COCOYL GLYCINATE,WATER/AQUA/EAU,ORYZA SATIVA (RICE) GERM POWDER,KAOLIN,POTASSIUM CHLORIDE,MONTMORILLONITE,CHARCOAL POWDER,SALICYLIC ACID,CITRUS GRANDIS (GRAPEFRUIT) PEEL OIL,NIACINAMIDE,EUCALYPTUS GLOBULUS LEAF OIL,MALTODEXTRIN,COCONUT ACID,POTASSIUM COCOATE,SODIUM HYALURONATE,SODIUM STARCH OCTENYLSUCCINATE,CALCIUM PANTOTHENATE,SODIUM PHYTATE,ETHYLHEXYLGLYCERIN,SODIUM ASCORBYL PHOSPHATE,PYRIDOXINE HCL,TOCOPHERYL ACETATE,LACTOBACILLUS FERMENT,SILICA,GLYCERIN,TOCOPHEROL,CAMELLIA SINENSIS LEAF EXTRACT | K31: FLACON,CAPSULE SERVICE,RECHARGEABLE | L31: 60 g | M31: USA | O31: 0
A32: OH MY CREAM SKINCARE - BLUSH | B32: OH MY CREAM | C32: SAS OH MY CREAM | D32: OH MY CREAM SKINCARE | E32: MAQUILLAGE | F32: JOUES | G32: FARD À JOUES/BLUSH,POUDRE | H32: TOUS TYPES DE PEAUX | I32: À l’aide du Pinceau Blush, déposer la poudre sur le bombé des pommettes et estomper vers les tempes. Intensifier la couleur si nécessaire. | J32: INCI TEINTE "ROSE" : MICA,ZINC STEARATE,C12-15 ALKYL BENZOATE,LAUROYL LYSINE,SODIUM STARCH OCTENYLSUCCINATE,OCTYLDODECYL STEAROYL STEARATE,SILICA,CAPRYLIC/CAPRIC TRIGLYCERIDE,ETHYLHEXYLGLYCERIN,COCO-CAPRYLATE/CAPRATE,CALCIUM CARBONATE,TOCOPHERYL ACETATE,CARTHAMUS TINCTORIUS SEED OIL,ALOE BARBADENSIS LEAF EXTRACT,MAGNESIUM STEARATE,TOCOPHEROL,+/- (MAY CONTAIN),CI 45410 (RED 28 LAKE),CI 15850 (RED 6),CI 77492 (IRON OXIDES),CI 77491 (IRON OXIDES),CI 42090 (BLUE 1 LAKE),CI 77499 (IRON OXIDES) | K32: BOÎTIER | L32: 4 g | M32: FRANCE | O32: 1
A33: MAGIC POWDERS - NETTOYANT VISAGE - EXFOLIANT QUOTIDIEN EN POUDRE | B33: WAAM | C33: DIECE SAS | D33: MAGIC POWDERS | E33: SOIN VISAGE | F33: VISAGE | G33: DÉMAQUILLANT/NETTOYANT,POUDRE,ANHYDRE | H33: TOUS TYPES DE PEAUX | I33: 1. Verser une noisette dans votre main. 2. Ajouter quelques gouttes d'eau. 3. Masser votre visage pour le nettoyer. De très légers grains peuvent se faire ressentir pour une action micro-exfoliante. 4. Rincer. | J33: SODIUM COCOYL GLUTAMATE,ZEA MAYS (CORN) STARCH*,MICROCRYSTALLINE CELLULOSE,ORYZA SATIVA (RICE) POWDER*,ALTHAEA OFFICINALIS ROOT*,ZINC PCA,PARFUM (FRAGRANCE),ALOE BARBADENSIS LEAF POWDER* | K33: FLACON SALIÈRE,RECHARGEABLE | L33: 50 g | M33: FRANCE | N33: 3700851107589 | O33: 0
A34: [ L'APPEL DE LA FORÊT ] - LA POUDRE MAGIQUE ÉCLAT & JEUNESSE | B34: GARANCIA | C34: GARANCIA, INC | D34: [ L'APPEL DE LA FORÊT ] | E34: SOIN VISAGE | F34: VISAGE,COU | G34: SOIN,POUDRE | H34: TOUS TYPES DE PEAUX | I34: Déposez une cuillère doseuse de poudre remplie à ras dans le creux de votre main puis ajoutez 5 à 7 gouttes du sérum double phase L'APPEL DE LA FORÊT booster de vitamine C (pour augmenter de +50% son pouvoir antioxydant). Mixez le tout avec votre doigt, la poudre fond littéralement. Appliquez matin et soir sur le visage. | J34: DIATOMACEOUS EARTH,ASCORBIC ACID,MICROCRYSTALLINE CELLULOSE,GLYCERIN,INULIN,PINUS STROBUS BARK EXTRACT,NICOTIANA BENTHAMIANA HEXAPEPTIDE-40 SH-POLYPEPTIDE-47,MALTODEXTRIN,AQUA (WATER/EAU),PENTYLENE GLYCOL | K34: POT | L34: 6 g | M34: FRANCE | N34: 3700928802409 | O34: 0
A35: POUDRE COMPACTE CERTIFIÉ BIO ET VÉGAN | B35: JCH RESPECT | C35: SARL JCH International | E35: MAQUILLAGE | F35: VISAGE,COU | G35: POUDRE,COMPACT | H35: TOUTES CARNATIONS | I35: Après votre BB crème ou seule après votre crème de jour, prélevez votre poudre à l’aide votre pinceau poudre, tapotez légèrement votre pinceau pour enlever l’excèdent, avant de l’appliquer sur votre visage. Commencez par le front puis sur les joues en balayant toujours de l’intérieur vers l’extérieur. N’oubliez pas votre cou. | J35: MICA,ZEA MAYS STARCH/ZEA MAYS (CORN) STARCH*,ZINC STEARATE,OCTYLDODECANOL,SQUALANE,BENZYL ALCOHOL,LECITHIN,LIMONENE,PRUNUS AMYGDALUS DULCIS OIL*,BUTYROSPERMUM PARKII BUTTER*,PARFUM (FRAGRANCE),DEHYDROACETIC ACID,TOCOPHEROL,ASCORBYL PALMITATE,CITRUS AURANTIUM DULCIS PEEL OIL*,CITRIC ACID,LINALOOL,+/- (MAY CONTAIN),CI 77891 (TITANIUM DIOXIDE),CI 77492 (IRON OXIDES),CI 77491 (IRON OXIDES),CI 77499 (IRON OXIDES) | K35: BOÎTIER | L35: 9 g | M35: ITALIE | O35: 1
A36: ILLUMINATEUR CERTIFIÉ BIO ET VÉGAN | B36: JCH RESPECT | C36: SARL JCH International | E36: MAQUILLAGE | F36: VISAGE | G36: ENLUMINEUR,POUDRE | H36: TOUTES CARNATIONS | I36: Il s’applique en touche finale sur les parties bombées du visage. Débutez par les yeux, afin d’agrandir votre regard, déposez une touche d’illuminateur au niveau de l’arcade sourcilière, juste en dessous du sourcil et terminez par le coin interne de l’œil. Passez ensuite aux pommettes, balayez légèrement sur le haut de vos pommettes de l’intérieur vers l’extérieurs. Vous pouvez si vous souhaitez affiner votre nez, tracer une ligne le long de son arête. Appliquez une légère touche d’illuminateur dans le creux qui se situe entre votre lèvre supérieure et votre nez (l’arc de cupidon). | J36: MICA,ZEA MAYS STARCH/ZEA MAYS (CORN) STARCH*,CI 77891 (TITANIUM DIOXIDE),SQUALANE,CAPRYLIC/CAPRIC TRIGLYCERIDE,OCTYLDODECANOL,ZINC STEARATE,CI 77491 (IRON OXIDES),BENZYL ALCOHOL,LIMONENE,LECITHIN,PRUNUS AMYGDALUS DULCIS OIL*,BUTYROSPERMUM PARKII BUTTER*,PARFUM (FRAGRANCE),DEHYDROACETIC ACID,TOCOPHEROL,ASCORBYL PALMITATE,CITRUS AURANTIUM DULCIS PEEL OIL*,CITRIC ACID,LINALOOL | K36: BOÎTIER | L36: 9 g | M36: ITALIE | O36: 1
A37: SUPERIOR SERUM - CALM REVIVAL GREEN TEA RESVERATROL POWDER | B37: EXPONENT | C37: Exponent Beauty, Inc. | E37: SOIN VISAGE | F37: VISAGE | G37: SOIN,POUDRE | H37: TOUS TYPES DE PEAUX,CONVIENT AUX PEAUX SENSIBLES/RÉACTIVES | I37: UTILISATION - AVEC Calm Revival peut être utilisé le matin ou le soir. Appliquer sur une peau humide et propre et recouvrir d'une crème hydratante ou d'un SPF. - COMMENT Votre sérum est activé lorsqu'il est entièrement dissous, généralement dans les 8 secondes qui suivent la combinaison de la poudre active et de l'hydratant. - UN MÉLANGE FACILE Les poudres actives peuvent être utilisées de manière interchangeable dans notre activateur avec le même hydratant, ce qui vous permet de combiner facilement votre routine matin et soir. - UNE NOTE SUR LE NETTOYAGE Le resvératrol s'oxyde rapidement. Si vous laissez des résidus dans votre bol, il commencera à brunir en quelques heures. Pour éviter cela, après le dosage, rincez votre bol sous le robinet et laissez-le sécher à l'air libre. COMMENT ÇA MARCHE ? - DOSEZ-LE Retirez le capuchon en caoutchouc du distributeur. Placez votre Globe + distributeur sur le bol, côté distributeur vers le bas. Poussez doucement le Globe vers le bas et tournez-le dans le sens des aiguilles d'une montre. Vous entendrez quelques petits clics puis un "bruit sourd" à environ 90 degrés. - FOUETTEZ LE Soulever le couvercle pour révéler une dose de liquide et deux tas de poudre. Fouettez le tout pendant environ 5 secondes jusqu'à ce qu'il se transforme en un sérum crème-gel léger. Prélevez tout ce qu'il y a de bon et appliquez-le sur votre visage et votre cou. - NETTOYEZ-LE Votre bol peut être rapidement essuyé avec un mouchoir en papier entre deux utilisations ou rincé et laissé à sécher à l'air libre. | J37: BETAINE,DIMETHICONE CROSSPOLYMER,DIMETHICONE,SILICA,CALCIUM SILICATE,HYDROXYETHYL ACRYLATE/SODIUM ACRYLOYLDIMETHYL TAURATE COPOLYMER,EPIGALLOCATECHIN GALLATE,DISTARCH PHOSPHATE,WATER (AQUA),CITRIC ACID,RESVERATROL,ASIATICOSIDE,QUERCETIN,ALOE BARBADENSIS LEAF JUICE,BUTYROSPERMUM PARKII (SHEA) BUTTER,PHENOXYETHANOL,POTASSIUM SORBATE,ETHYLHEXYLGLYCERIN,ANTHEMIS NOBILIS (ROMAN CHAMOMILE) OIL,MICA,TITANIUM DIOXIDE (CI 77891) | K37: POT,RECHARGEABLE | L37: 6 g | M37: USA | O37: 0
A38: PLEIN AIR - POUDRE ÉCLAT RAYONNANT | B38: HERMÈS | C38: HERMÈS INTERNATIONAL | D38: PLEIN AIR | E38: MAQUILLAGE | F38: JOUES | G38: FARD À JOUES/BLUSH,POUDRE,COMPACT | H38: TOUS TYPES DE PEAUX,TOUTES CARNATIONS | I38: Appliquez la poudre éclat rayonnant sur peau nue ou après le rituel de teint pour illuminer les pommettes, les tempes, l'arête du nez ou l'arc de Cupidon, au doigt ou à l'aide du pinceau fard à joues Rose Hermès. | J38: MICA,SQUALANE,OCTYLDODECYL STEAROYL STEARATE,GLYCERIN,SILICA,HDI/TRIMETHYLOL HEXYLLACTONE CROSSPOLYMER,ZINC STEARATE,KAOLIN,SYNTHETIC FLUORPHLOGOPITE,PENTYLENE GLYCOL,CAPRYLYL GLYCOL,DICALCIUM PHOSPHATE,SORBITAN SESQUIISOSTEARATE,PARFUM (FRAGRANCE),SODIUM DEHYDROACETATE,CAPRYLIC/CAPRIC TRIGLYCERIDE,TOCOPHEROL,TOCOPHERYL ACETATE,CHONDRUS CRISPUS POWDER,XANTHAN GUM,MORUS ALBA BARK EXTRACT,BENZYL SALICYLATE,LIMONENE,GERANIOL,CITRONELLOL,LINALOOL,HYDROXYCITRONELLAL,CI 77891 (TITANIUM DIOXIDE),CI 77491 (IRON OXIDES) | K38: BOÎTIER,RECHARGEABLE | L38: 8,5 g | M38: ITALIE | N38: 3346130412212 | O38: 1
A39: TERRACOTTA LIGHT - LA POUDRE ÉCLAT BONNE MINE NATURELLE | B39: GUERLAIN | C39: LVMH | D39: TERRACOTTA | E39: MAQUILLAGE | F39: VISAGE,COU | G39: ENLUMINEUR,POUDRE | H39: TOUTES CARNATIONS | I39: LE MOT DE VIOLETTE, DIRECTRICE DE LA CRÉATION DU MAQUILLAGE GUERLAIN : « MON SECRET POUR UN EFFET SUN-KISSED IRRÉSISTIBLE ? APPLIQUER LA TERRACOTTA SUR LES ZONES LES PLUS BOMBÉES COMME LES POMMETTES, L’ARÊTE DU NEZ ET LE HAUT DU FRONT POUR APPORTER PLUS DE STRUCTURE AU VISAGE TOUT EN RÉCHAUFFANT DÉLICATEMENT LE TEINT. » | J39: MICA,SILICA,LAUROYL LYSINE,ZINC STEARATE,BIS-BEHENYL/ISOSTEARYL/PHYTOSTERYL DIMER DILINOLEYL DIMER DILINOLEATE,OCTYLDODECYL STEAROYL STEARATE,DICAPRYLYL ETHER,CELLULOSE,CALCIUM SODIUM BOROSILICATE,DIMER DILINOLEYL DIMER DILINOLEATE,KAOLIN,PARFUM (FRAGRANCE),CAPRYLYL GLYCOL,ETHYLHEXYLGLYCERIN,SODIUM DEHYDROACETATE,PENTYLENE GLYCOL,AQUA (WATER),BUTYLENE GLYCOL,PROPANEDIOL,MEL (HONEY),GLYCERIN,TOCOPHEROL,TIN OXIDE,BUTYROSPERMUM PARKII SEEDCAKE EXTRACT,+/- (MAY CONTAIN),CI 77891 (TITANIUM DIOXIDE),CI 77163 (BISMUTH OXYCHLORIDE),CI 77491, CI 77492, CI 77499 (IRON OXIDES),CI 73360 (RED 30 LAKE) | K39: BOÎTIER | L39: 10 g | M39: FRANCE | N39: 3346470435612 | O39: 1
A40: PRISME LIBRE PRESSED POWDER - POUDRE FIXATRICE MATIFIANTE & FLOUTANTE | B40: GIVENCHY | C40: LVMH | D40: PRISME LIBRE | E40: MAQUILLAGE | F40: VISAGE | G40: POUDRE,COMPACT | H40: TOUTES CARNATIONS | I40: La poudre compacte Prisme Libre Pressed Powder s'applique seule pour matifier le teint ou après le fond de teint pour fixer et sculpter le maquillage. LA PERFECTION MATE EN 3 ÉTAPES PRISMATIQUES 1. MÉLANGER les 4 couleurs avec le pinceau pour un résultat homogène. 2. APPLIQUER la poudre du centre vers l'extérieur en privilégiant la zone T, ou sur l'ensemble du visage pour un fini mat modulable. 3. ESTOMPER sur la peau pour créer le parfait look mat et lumineux à l'effet floutant. | J40: TALC,SYNTHETIC FLUORPHLOGOPITE,SILICA,ZINC STEARATE,DIMETHICONE,DIISOSTEARYL MALATE,OCTYLDODECYL STEAROYL STEARATE,CAPRYLYL GLYCOL,PENTYLENE GLYCOL,PHENYL TRIMETHICONE,SODIUM DEHYDROACETATE,PARFUM (FRAGRANCE),SORBITAN SESQUIOLEATE,TOCOPHERYL ACETATE,HYDROLYZED SERICIN,KAOLIN,+/- (MAY CONTAIN),CI 77891 (TITANIUM DIOXIDE),CI 77007 (ULTRAMARINES),CI 77491, CI 77492 (IRON OXIDES),CI 19140 (YELLOW 5 LAKE),CI 77742 (MANGANESE VIOLET),CI 15850 (RED 6),CI 42090 (BLUE 1 LAKE),CI 73360 (RED 30 LAKE) | K40: BOÎTIER | L40: 9,5 g | M40: ITALIE | O40: 1
...

Sheet clean
A1: NAME | B1: BRAND | C1: COSMETIC CATEGORY | D1: APPLICATION ZONE | E1: PRODUCT TYPE | F1: COSMETIC TARGET | G1: HOW TO USE | H1: INGREDIENTS | I1: PACKAGING | J1: CAPACITY | K1: MADE IN | L1: CODE EAN | M1: link | N1: price
A2: voile caresse spf 15 | B2: bareminerals | C2: maquillage | D2: visage | E2: foundation,powder,compact | F2: toutes carnations | G2: à appliquer en lissage avec le pinceau application visage zéro défaut. | H2: alaria esculenta extract, ascorbyl palmitate, bambusa arundinacea stem powder, benzyl benzoate, benzyl salicylate, boron nitride, camellia sinensis (green tea) leaf extract, cananga odorata flower oil, caprylic/capric triglyceride, cetyl phosphate, coco-caprylate, corallina officinalis extract, geraniol, iron oxides, jojoba esters, lauroyl lysine, linalool, mica, silica, jojoba oil, tocopherol, vitis vinifera (grape) seed oil, zinc oxide, titanium dioxide | I2: boîtier | J2: 10 g | K2: canada
A3: all hours - hyper luminize - poudre illuminatrice versatile | B3: yves saint laurent | C3: maquillage | D3: visage | E3: highlighter,powder | F3: tous types de peaux | G3: appliquez all hours hyper luminize sur les points saillants du visage : pommettes, arête du nez, arc de cupidon et coin interne de l'œil. estompez délicatement au doigt ou au pinceau. | H3: synthetic fluorphlogopite, c12-15 alkyl benzoate, dimethicone, titanium dioxide, mica, calcium aluminum borosilicate, talc, hydrogenated polyisobutene, glass beads, boron nitride, magnesium stearate, ci 77491, silica, hydrogenated styrene/butadiene copolymer, caprylyl glycol, niacinamide, sodium hyaluronate, caprylic/capric triglyceride, sorbitan isostearate, isododecane, methicone, ci 75470, ci 77861, citrus limon peel extract, tris-bht mesitylene, tocopherol | I3: boîtier | J3: 5 g | K3: france | L3: 3614274197044
A4: blush poudre | B4: le rouge français | C4: maquillage | D4: joues | E4: blush,powder | F4: toutes carnations | G4: le blush poudre s’applique après avoir préparé et unifié la base teint. à l’aide du pinceau kabuki intégré, prélevez une petite quantité de poudre en tapotant pour contrôler sa quantité. retirez l’excédent et appliquez par mouvements circulaires sur les zones bombées de votre visage, comme les pommettes. pour intensifier le résultat, répétez l’application par légères touches jusqu’à obtenir le fini souhaité, naturel ou sophistiqué. | H4: talc, tapioca starch, ci 77007, zinc oxide, kaolin, mica, rubia tinctorum root*, coco-caprylate/caprate, squalane, glyceryl caprylate, shea butter, jojoba oil, zinc stearate, tocopherol, argania spinosa kernel oil, glyceryl undecylenate, sunflower seed oil | I4: boîtier | J4: 9 g | K4: france
A5: les tarots de chanel - poudre blush mate | B5: chanel | C5: maquillage | D5: joues | E5: blush,powder | F5: toutes carnations | G5: appliquer la création exclusive les tarots de chanel sur les pommettes à l'aide du pinceau inclus pour apporter de la couleur au teint. appliquer une touche légère pour un maquillage naturel. ajouter une seconde touche pour intensifier le résultat. | H5: synthetic fluorphlogopite, zinc stearate, squalane, caprylyl glycol, ethylhexylglycerin, aluminum hydroxide, water, alcohol, glycerin, tocopherol, polysorbate 80 | I5: boîtier | J5: 14 g | K5: italie | L5: 3145891517286
A6: teint idole ultra wear - c.e. skin transforming highlighter | B6: lancôme | C6: maquillage | D6: visage | E6: highlighter,powder | F6: tous types de peaux,toutes carnations | G6: appliquer advance génifique et masser vers le haut du visage pour une peau instantanément hydratée. appliquer le fond de teint teint idole ultra wear pour une couverture parfaite. appliquer ensuite un correcteur pour un effet lumineux et lifté. bronzez instantanément votre peau avec le nouveau teint idole ultra wear c.e. skin transforming bronzer. utilisez un pinceau large et appliquez-le par mouvements circulaires là où le soleil se pose naturellement sur la peau (joues, nez, tempes et menton). highlightez les zones naturelles de lumière avec le nouveau teint idole ultra wear c.e. skin transforming highlighter. utilisez un pinceau large et appliquez-le là où la lumière illumine votre visage (haut des joues, nez, menton). | H6: talc, caprylic/capric triglyceride, dimethicone, zinc stearate, silica, corn starch, punica granatum pericarp extract, moringa oleifera seed oil, alaria esculenta extract, isododecane, dimethicone/vinyl dimethicone crosspolymer, dimethiconol, silica [nano]/silica, trimethylsiloxysilicate, ascorbyl tetraisopalmitate, caprylyl glycol, ethylhexylglycerin, tocopherol, potassium sorbate, parfum, linalool, limonene | I6: boîtier | J6: 10 g | K6: italie | L6: 3614274110470
A7: les beiges - poudre belle mine ensoleillée 2024 | B7: chanel | C7: maquillage | D7: visage,cou,buste/décolleté | E7: highlighter,powder | F7: toutes carnations,tous types de peaux | G7: pour une application simple et intuitive, prélever les trois poudres en un seul geste avec le pinceau poudre n°106. appliquer sur les pommettes et à l’envi sur le front, les tempes, le nez et le menton pour réchauffer l’ensemble du visage. pour une application plus structurée, utiliser le pinceau poudre n°106 pour appliquer les différents tons de les beiges poudre belle mine ensoleillée. - appliquer la poudre bronzante sur les pommettes en commençant par l'extérieur du visage et en terminant par le milieu de la joue, en effectuant des mouvements circulaires. cette teinte peut également être appliquée sur le front, les tempes, le nez et le menton pour donner plus de chaleur à l'ensemble du visage. - appliquer le blush en l’étirant des pommettes vers l’extérieur pour rehausser les pommettes. - appliquer l’highlighter sur le haut des pommettes pour rehausser le teint et apporter une touche supplémentaire de lumière. | H7: synthetic fluorphlogopite, lauroyl lysine, zinc stearate, boron nitride, octyldodecyl stearoyl stearate, corn starch, octyldodecanol, jasminum grandiflorum (jasmine) flower extract, 1-2-hexanediol, caprylyl glycol, parfum, ethylhexyl palmitate, kaolin, tocopheryl acetate, silica | I7: boîtier | J7: 15 g | K7: italie | L7: 3145891863703
A8: ombre essentielle - ombre à paupières longue tenue multi-usage | B8: chanel | C8: maquillage | D8: paupières | E8: eyeshadow,compact,powder | F8: convient aux porteurs de lentilles | G8: avec ombre essentielle, affirmer son look en jouant sur 3 applications différentes, à porter seules ou en accumulation : - ombrer l’intégralité des paupières d’une couleur intense et lumineuse. - accentuer le regard d’un simple trait d’eye-liner aussi graphique que subtil. - intensifier les sourcils d’une pointe de couleur audacieuse pour un look singulier. humidifier légèrement le pinceau eye-liner biseauté afin d’obtenir un fini précis et une couleur intensifiée. | H8: synthetic fluorphlogopite, octyldodecyl stearoyl stearate, dimethicone, polybutene, trimethylsiloxysilicate, cellulose, hydrogen dimethicone, caprylyl glycol, magnesium stearate, potassium sorbate, silica, chlorphenesin, tocopheryl acetate, dimethicone crosspolymer, salvia hispanica seed oil, tocopherol | I8: boîtier | J8: 1,9 g | K8: france | L8: 3145891812268
A9: météorites - perles de poudre révélatrices de lumière - nouvelle formule 2024 | B9: guerlain | C9: maquillage | D9: visage | E9: highlighter,pearls,powder | F9: toutes carnations | G9: utiliser le pinceau météorites pour appliquer uniformément sur l’ensemble du visage, pour fixer le maquillage et améliorer sa tenue. pour un éclat boosté, illuminer les parties bombées : dessiner un g du centre du front vers les tempes, les pommettes et le haut du nez en redescendant jusqu’à la pointe du menton. | H9: mica, distarch, silica, magnesium myristate, synthetic fluorphlogopite, cellulose, magnesium carbonate hydroxide, calcium sodium borosilicate, hydroxypropyl starch, caprylyl glycol, ethylhexylglycerin, parfum, sodium dehydroacetate, calcium aluminum borosilicate, sorbic acid, ci 77861, tocopherol | I9: boîtier | J9: 25 g | K9: france | L9: 3346470438781
A10: artist eyeshadow - nouvelle formule 2024 | B10: make up for ever | C10: maquillage | D10: paupières | E10: eyeshadow,powder | F10: toutes carnations | G10: 1/ prélever la matière avec le côté plat du pinceau #248. 2/ appliquer l'ombre à paupières sur la zone souhaitée en tapotant délicatement puis en effectuant des mouvements de balayage avec la partie plate du pinceau. 3/ avec le côté rond du pinceau #248, estomper avec de petits mouvements circulaires, puis d'avant en arrière. | H10: synthetic fluorphlogopite, dimethicone, zinc stearate, caprylyl glycol, pentylene glycol, ethylhexylglycerin, silica, diisostearyl malate, octyldodecyl stearoyl stearate, sodium dehydroacetate, kaolin, tocopheryl acetate, sorbitan sesquioleate, tocopherol | I10: boîtier | J10: 5 g
A11: lingerie de peau - fond de teint compact poudre | B11: guerlain | C11: maquillage | D11: visage | E11: foundation,powder,compact | F11: tous types de peaux,toutes carnations | G11: appliquer sur le visage à l’aide de l’éponge, puis étirer à volonté pour obtenir la couvrance idéale, du centre du visage vers l’extérieur et le cou. | H11: barium sulfate, talc, synthetic fluorphlogopite, silica, ethylhexyl methoxycinnamate, cellulose, dimethicone, hydrogenated polyisobutene, mica, pentylene glycol, acrylates/stearyl acrylate/dimethicone methacrylate copolymer, diisostearyl malate, decyloxazolidinone, octyldodecyl stearoyl stearate, sodium dehydroacetate, jojoba esters, caprylyl glycol, aluminum hydroxide, dimethicone/methicone copolymer, palmitic acid, isopropyl titanium triisostearate, parfum, water, sodium lauroyl aspartate, hyaluronic acid, butylphenyl methylpropional, magnesium hydroxide, zinc chloride, linalool, bht, citronellol, alpha-isomethyl ionone, sericin, benzyl benzoate, geraniol, hydrolyzed linseed extract, phenoxyethanol, tocopherol, citric acid, potassium sorbate | I11: boîtier | J11: 10 g | K11: france
A12: ombre d'hermès - palette de couleurs quatuor ombres pour les yeux | B12: hermès | C12: maquillage | D12: paupières | E12: eyeshadow,powder | F12: tous types de peaux | G12: appliquer et estomper sur les paupières à l'aide de votre pinceau préféré. si vous le souhaitez, mouillez légèrement le pinceau avant l'application pour amplifier l'intensité et la précision de la couleur. | H12: mica, calcium sodium borosilicate, caprylic/capric triglyceride, octyldodecyl stearoyl stearate, zinc stearate, methylpropanediol, phenoxyethanol, caprylyl glycol, sodium dehydroacetate, ci 77861, phenylpropanol, cellulose, magnesium stearate, morus alba bark extract | I12: boîtier,rechargeable | J12: 3 g | K12: italie | L12: 3346130411314
A13: goof proof brow powder - easy brow filling powder | B13: benefit | C13: maquillage | D13: sourcils | E13: powder,compact | G13: apply with an angled brush to outline brows, shape and define. use light strokes to fill in sparse brow areas and layer to build color. blend with spoolie. | H13: mica, synthetic fluorphlogopite, dimethicone, trimethylsiloxysilicate, microcrystalline cellulose, kaolin, magnesium stearate, triethoxycaprylylsilane, magnesium myristate, ricinus communis (castor) seed oil, phenoxyethanol, sorbic acid, caprylyl glycol, tocopherol, sunflower seed oil | I13: boîtier | J13: 1,9 g | K13: france | L13: 0602004140357
A14: terracotta luminizer - la poudre enlumineur | B14: guerlain | C14: maquillage | D14: visage | E14: highlighter,powder | F14: toutes carnations | G14: la poudre enlumineur terracotta luminizer peut s’utiliser sur le fond de teint ou la peau nue. appliquer en touches sur le haut des pommettes, l’arête du nez et l’arc de cupidon, pour un maquillage sensuel, éclatant et scintillant. étirer sous l’arcade sourcilière, ou en ombre à paupières, pour un regard subtilement illuminé. | H14: mica, caprylic/capric triglyceride, silica, alumina, c13-15 alkane, coco-caprylate/caprate, polyglyceryl-3 polyricinoleate, polyglyceryl-4 caprate, butylene glycol, triheptanoin, glycerin, c9-12 alkane, parfum, dilinoleic acid/butanediol copolymer, caprylyl glycol, ethylhexylglycerin, triethoxycaprylylsilane, 1-2-hexanediol, lauroyl lysine, polyglyceryl-3 diisostearate, gellan gum, calcium chloride, castor oil, argania spinosa kernel oil, tocopherol | I14: boîtier | J14: 7 g | K14: france | L14: 3346470435667
A15: double wear - poudre de teint mat | B15: estée lauder | C15: maquillage | D15: visage | E15: foundation,powder,compact | F15: tous types de peaux,toutes carnations | G15: trouvez la teinte parfaite : choisissez d’abord l’intensité de la teinte (de clair à foncé, soit de 0 à 8), puis le sous-ton (rosé : c , neutre : n ou chaud : w). comment déterminer son sous-ton ? le sous-ton caractérise l’apparence de la peau nue et la manière dont elle réagit.lequel des sous-tons ci-dessous vous ressemble le plus ? - rosé (c) : la peau a une teinte rosée naturelle et attrape facilement des coups de soleil. - neutre (n) : la peau n’est ni totalement rosée ni totalement dorée mais entre les deux. | H15: boron nitride, polymethylsilsesquioxane, octyldodecyl stearoyl stearate, silica, calcium silicate, isostearyl neopentanoate, tocopheryl acetate, dimethicone, methicone, phenyl trimethicone, titanium dioxide, talc, triethoxycaprylylsilane, trimethylsiloxysilicate, methyl methacrylate crosspolymer, sodium lauroyl aspartate, caprylyl glycol, hexylene glycol, zinc stearate, isopropyl titanium triisostearate, phenoxyethanol | I15: boîtier,applicateur éponge | J15: 12 g | K15: u.k.
